2020-10-22 04:57:55  ERROR - tasks_cmsGrabApi.py:55  - postmap_send
2020-10-22 05:04:29  ERROR - tasks_cmsGrabApi.py:55  - postmap_send
2020-11-23 23:52:37   INFO - flaskSchedulerUnits.py:23  - flask start
2020-11-23 23:53:36  ERROR - tasks_cmsGrabApi.py:55  - postmap_send
2020-11-23 23:53:36  ERROR - tasks_cmsGrabApi.py:77  - execute : {'type': 'SettingsError', 'traceback': 'Traceback (most recent call last):\n  File "/headless/app/projects/MiscLib/Utils.py", line 532, in GetConfigYamlRawData\n    with open(yaml_path, \'r\',encoding=encoding) as stream :\nFileNotFoundError: [Errno 2] No such file or directory: \'/headless/app/config_yaml/opencms_yaml/sender-bobae-silo.yaml\'\n\nDuring handling of the above exception, another exception occurred:\n\nTraceback (most recent call last):\n  File "/headless/app/projects/OpenCMS/tasks/tasks_cmsGrabApi.py", line 61, in execute\n    is_valid,result = execute_postmapSend(client,param_info,option_info)\n  File "/headless/app/projects/OpenCMS/tasks/tasks_cmsGrabApi.py", line 172, in execute_postmapSend\n    crawler.executeSpider()\n  File "/headless/app/projects/OpenCMS/core/wpCrawlerUnits.py", line 312, in executeSpider\n    self.grabSpider.crawling(self.target_session)\n  File "/headless/app/projects/OpenCMS/core/wpCrawlerUnits.py", line 101, in grabSpider\n    self.__grabSpider = self._getGrabSpider()\n  File "/headless/app/projects/OpenCMS/core/wpCrawlerUnits.py", line 111, in _getGrabSpider\n    if self.grabber_type in ["wp_cms_grab"] :\n  File "/headless/app/projects/OpenCMS/core/wpCrawlerUnits.py", line 96, in grabber_type\n    return self.grab_config.get("grabber_type")\n  File "/headless/app/projects/OpenCMS/core/wpCrawlerUnits.py", line 92, in grab_config\n    self.__grab_config = self.client.getGrabConfig(self.grab_name)\n  File "/headless/app/projects/OpenCMS/clients/wpGrabClientUnits.py", line 38, in getGrabConfig\n    default_config = self.crawler_config.get("default_config",dict())\n  File "/headless/app/projects/OpenCMS/clients/wpGrabClientUnits.py", line 29, in crawler_config\n    return self.app_config.get("crawler_config")\n  File "/headless/app/projects/SchedLib/ClientUnits/baseSchedClientUnits.py", line 66, in app_config\n    return self.yaml_config.get("app_config",dict())\n  File "/headless/app/projects/CeleryLib/ClientUnits/baseCeleryClientUnits.py", line 55, in yaml_config\n    self.__yaml_config = self.yaml_celery_config\n  File "/headless/app/projects/CeleryLib/ClientUnits/baseCeleryClientUnits.py", line 44, in yaml_celery_config\n    return self._get_yaml_celery_config(self.YAML_CONFIG_FILENAME,self.YAML_SUBDIR)\n  File "/headless/app/projects/CeleryLib/ClientUnits/baseCeleryClientUnits.py", line 50, in _get_yaml_celery_config\n    return Utils.GetConfigYamlRawData(filename,subdir,encoding="utf8")\n  File "/headless/app/projects/MiscLib/Utils.py", line 535, in GetConfigYamlRawData\n    raise SettingsError(e)\nMiscLib.Utils.GetConfigYamlRawData.<locals>.SettingsError: [Errno 2] No such file or directory: \'/headless/app/config_yaml/opencms_yaml/sender-bobae-silo.yaml\'\n', 'msg': "[Errno 2] No such file or directory: '/headless/app/config_yaml/opencms_yaml/sender-bobae-silo.yaml'"} 
 - param_info : {'grab_config': {'client_name': 'sender-bobae-silo.yaml', 'grab_name': 'bobae_sender'}, 'proto': 'postmap_send', 'send_class': 'postmap', 'execute_spider': True, 'request_name': 'bobae-silo'} 

2020-11-23 23:55:38  ERROR - tasks_cmsGrabApi.py:55  - postmap_send
2020-11-23 23:55:40  ERROR - tasks_cmsGrabApi.py:77  - execute : {'type': 'InternalError', 'traceback': 'Traceback (most recent call last):\n  File "/usr/local/lib/python3.6/dist-packages/sqlalchemy/engine/base.py", line 1193, in _execute_context\n    context)\n  File "/usr/local/lib/python3.6/dist-packages/sqlalchemy/engine/default.py", line 509, in do_execute\n    cursor.execute(statement, parameters)\n  File "/usr/local/lib/python3.6/dist-packages/pymysql/cursors.py", line 170, in execute\n    result = self._query(query)\n  File "/usr/local/lib/python3.6/dist-packages/pymysql/cursors.py", line 328, in _query\n    conn.query(q)\n  File "/usr/local/lib/python3.6/dist-packages/pymysql/connections.py", line 516, in query\n    self._affected_rows = self._read_query_result(unbuffered=unbuffered)\n  File "/usr/local/lib/python3.6/dist-packages/pymysql/connections.py", line 727, in _read_query_result\n    result.read()\n  File "/usr/local/lib/python3.6/dist-packages/pymysql/connections.py", line 1066, in read\n    first_packet = self.connection._read_packet()\n  File "/usr/local/lib/python3.6/dist-packages/pymysql/connections.py", line 683, in _read_packet\n    packet.check_error()\n  File "/usr/local/lib/python3.6/dist-packages/pymysql/protocol.py", line 220, in check_error\n    err.raise_mysql_exception(self._data)\n  File "/usr/local/lib/python3.6/dist-packages/pymysql/err.py", line 109, in raise_mysql_exception\n    raise errorclass(errno, errval)\npymysql.err.InternalError: (1054, "Unknown column \'date_gmt\' in \'field list\'")\n\nThe above exception was the direct cause of the following exception:\n\nTraceback (most recent call last):\n  File "/headless/app/projects/OpenCMS/tasks/tasks_cmsGrabApi.py", line 61, in execute\n    is_valid,result = execute_postmapSend(client,param_info,option_info)\n  File "/headless/app/projects/OpenCMS/tasks/tasks_cmsGrabApi.py", line 172, in execute_postmapSend\n    crawler.executeSpider()\n  File "/headless/app/projects/OpenCMS/core/wpCrawlerUnits.py", line 312, in executeSpider\n    self.grabSpider.crawling(self.target_session)\n  File "/headless/app/projects/OpenCMS/grabbers/grabSpiderUnits.py", line 602, in crawling\n    is_dirty = self._posts_execute_mapping(grab_result,mapping_option,session=session)\n  File "/headless/app/projects/OpenCMS/grabbers/grabSpiderUnits.py", line 748, in _posts_execute_mapping\n    in_dirty = self.postmap_setRaw(post_list,session)\n  File "/headless/app/projects/OpenCMS/grabbers/grabSpiderUnits.py", line 400, in postmap_setRaw\n    is_dirty,in_row_list = postmap_cud.queryWithMode("set",postmap_args,session=session)\n  File "/headless/app/projects/OpenCMS/core/cudQueryBuilderUnits.py", line 891, in queryWithMode\n    return self.queryRun(default_value=default_value,session=session)\n  File "/headless/app/projects/OpenCMS/core/cudQueryBuilderUnits.py", line 884, in queryRun\n    result = self._query_execute(session=session)\n  File "/headless/app/projects/OpenCMS/core/cudQueryBuilderUnits.py", line 820, in _query_execute\n    in_dirty = self._query_insertExecute("insert_raw",insert_info_list,session=session )\n  File "/headless/app/projects/OpenCMS/core/cudQueryBuilderUnits.py", line 548, in _query_insertExecute\n    builder.execute_sql(sql ,session=session )\n  File "/headless/app/projects/OpenCMS/core/sqlBuilderUnits.py", line 220, in execute_sql\n    session.execute(sql_string)\n  File "/usr/local/lib/python3.6/dist-packages/sqlalchemy/orm/session.py", line 1176, in execute\n    bind, close_with_result=True).execute(clause, params or {})\n  File "/usr/local/lib/python3.6/dist-packages/sqlalchemy/engine/base.py", line 948, in execute\n    return meth(self, multiparams, params)\n  File "/usr/local/lib/python3.6/dist-packages/sqlalchemy/sql/elements.py", line 269, in _execute_on_connection\n    return connection._execute_clauseelement(self, multiparams, params)\n  File "/usr/local/lib/python3.6/dist-packages/sqlalchemy/engine/base.py", line 1060, in _execute_clauseelement\n    compiled_sql, distilled_params\n  File "/usr/local/lib/python3.6/dist-packages/sqlalchemy/engine/base.py", line 1200, in _execute_context\n    context)\n  File "/usr/local/lib/python3.6/dist-packages/sqlalchemy/engine/base.py", line 1413, in _handle_dbapi_exception\n    exc_info\n  File "/usr/local/lib/python3.6/dist-packages/sqlalchemy/util/compat.py", line 265, in raise_from_cause\n    reraise(type(exception), exception, tb=exc_tb, cause=cause)\n  File "/usr/local/lib/python3.6/dist-packages/sqlalchemy/util/compat.py", line 248, in reraise\n    raise value.with_traceback(tb)\n  File "/usr/local/lib/python3.6/dist-packages/sqlalchemy/engine/base.py", line 1193, in _execute_context\n    context)\n  File "/usr/local/lib/python3.6/dist-packages/sqlalchemy/engine/default.py", line 509, in do_execute\n    cursor.execute(statement, parameters)\n  File "/usr/local/lib/python3.6/dist-packages/pymysql/cursors.py", line 170, in execute\n    result = self._query(query)\n  File "/usr/local/lib/python3.6/dist-packages/pymysql/cursors.py", line 328, in _query\n    conn.query(q)\n  File "/usr/local/lib/python3.6/dist-packages/pymysql/connections.py", line 516, in query\n    self._affected_rows = self._read_query_result(unbuffered=unbuffered)\n  File "/usr/local/lib/python3.6/dist-packages/pymysql/connections.py", line 727, in _read_query_result\n    result.read()\n  File "/usr/local/lib/python3.6/dist-packages/pymysql/connections.py", line 1066, in read\n    first_packet = self.connection._read_packet()\n  File "/usr/local/lib/python3.6/dist-packages/pymysql/connections.py", line 683, in _read_packet\n    packet.check_error()\n  File "/usr/local/lib/python3.6/dist-packages/pymysql/protocol.py", line 220, in check_error\n    err.raise_mysql_exception(self._data)\n  File "/usr/local/lib/python3.6/dist-packages/pymysql/err.py", line 109, in raise_mysql_exception\n    raise errorclass(errno, errval)\nsqlalchemy.exc.InternalError: (pymysql.err.InternalError) (1054, "Unknown column \'date_gmt\' in \'field list\'") [SQL: \'INSERT INTO crw_wp_post_map (`sgid`, `date_gmt`, `date_gmt_time`, `update_time`, `seq_num`, `crw_num`, `title`, `content`, `source_link`, `link`, `meta`, `modified_gmt`, `modified_gmt_time`, `status`, `categories`, `cms_iden`, `grab_name`, `ID`, `grabber_type`) VALUES ("47a7aac92d0305319b1fae38c47ca9ce-v7GsUoJW-f87f87ef-84f3-4433-9845-39b64b565495", "2013-07-18T15:06:00", "2013-07-18T15:06:00", "2020-11-23 23:55:40", -1, 1, "국내 감동적인응급차 길터주기 모세의기적", "<p>\\xa0</p><iframe allowfullscreen=\\\\"\\\\" frameborder=\\\\"0\\\\" height=\\\\"360\\\\" src=\\\\"http://www.youtube.com/embed/zX8BwkB4Mfo?feature=player_detailpage\\\\" width=\\\\"640\\\\"></iframe>\\\\n<p>\\xa0</p>\\\\n<p>\\xa0</p>\\\\n<p><span style=\\\\"FONT-SIZE: 12pt\\\\">[펌]</span></p>\\\\n<p><span style=\\\\"FONT-SIZE: 12pt\\\\">이정도면 선진국 아닌가요? 여러분 모두 할 수 있는 </span></p>\\\\n<p><span style=\\\\"FONT-SIZE: 12pt\\\\">그런 평범한 일입니다 조금만 움직이면 한 생명을 살릴수 있습니다 </span></p>\\\\n<p><span style=\\\\"FONT-SIZE: 12pt\\\\">저부터 실천 하겠습니다 (소리주의)</span></p>", "https://www.bobaedream.co.kr/view?code=best&No=26230&vdate=h", "https://commu-crw.moagun.xyz/?p=1087", "[{\\\\"meta_key\\\\": \\\\"is_comment_box\\\\", \\\\"meta_value\\\\": \\\\"1\\\\"}, {\\\\"meta_key\\\\": \\\\"comment_box\\\\", \\\\"meta_value\\\\": \\\\"{\\\\\\\\\\\\"box\\\\\\\\\\\\": \\\\\\\\\\\\"bobae\\\\\\\\\\\\", \\\\\\\\\\\\"comment_list\\\\\\\\\\\\": [{\\\\\\\\\\\\"is_remove\\\\\\\\\\\\": false, \\\\\\\\\\\\"index\\\\\\\\\\\\": 2, \\\\\\\\\\\\"has_childs\\\\\\\\\\\\": false, \\\\\\\\\\\\"child_count\\\\\\\\\\\\": 0, \\\\\\\\\\\\"comment_author\\\\\\\\\\\\": \\\\\\\\\\\\"익명-9194\\\\\\\\\\\\", \\\\\\\\\\\\"comment_content\\\\\\\\\\\\": \\\\\\\\\\\\"오메 소름!\\\\\\\\\\\\", \\\\\\\\\\\\"comment_karma\\\\\\\\\\\\": 0, \\\\\\\\\\\\"comment_date\\\\\\\\\\\\": \\\\\\\\\\\\"2013-07-18 15:22:00\\\\\\\\\\\\", \\\\\\\\\\\\"comment_date_gmt\\\\\\\\\\\\": \\\\\\\\\\\\"2013-07-18 06:22:00\\\\\\\\\\\\", \\\\\\\\\\\\"level\\\\\\\\\\\\": 1}, {\\\\\\\\\\\\"is_remove\\\\\\\\\\\\": false, \\\\\\\\\\\\"index\\\\\\\\\\\\": 3, \\\\\\\\\\\\"has_childs\\\\\\\\\\\\": false, \\\\\\\\\\\\"child_count\\\\\\\\\\\\": 0, \\\\\\\\\\\\"comment_author\\\\\\\\\\\\": \\\\\\\\\\\\"익명-1930\\\\\\\\\\\\", \\\\\\\\\\\\"comment_content\\\\\\\\\\\\": \\\\\\\\\\\\"굿...\\\\\\\\\\\\", \\\\\\\\\\\\"comment_karma\\\\\\\\\\\\": 0, \\\\\\\\\\\\"comment_date\\\\\\\\\\\\": \\\\\\\\\\\\"2013-07-18 15:28:00\\\\\\\\\\\\", \\\\\\\\\\\\"comment_date_gmt\\\\\\\\\\\\": \\\\\\\\\\\\"2013-07-18 06:28:00\\\\\\\\\\\\", \\\\\\\\\\\\"level\\\\\\\\\\\\": 1}, {\\\\\\\\\\\\"is_remove\\\\\\\\\\\\": false, \\\\\\\\\\\\"index\\\\\\\\\\\\": 4, \\\\\\\\\\\\"has_childs\\\\\\\\\\\\": false, \\\\\\\\\\\\"child_count\\\\\\\\\\\\": 0, \\\\\\\\\\\\"comment_author\\\\\\\\\\\\": \\\\\\\\\\\\"익명-1930\\\\\\\\\\\\", \\\\\\\\\\\\"comment_content\\\\\\\\\\\\": \\\\\\\\\\\\"많은분들 볼수있게 추�V...\\\\\\\\\\\\", \\\\\\\\\\\\"comment_karma\\\\\\\\\\\\": 0, \\\\\\\\\\\\"comment_date\\\\\\\\\\\\": \\\\\\\\\\\\"2013-07-18 15:29:00\\\\\\\\\\\\", \\\\\\\\\\\\"comment_date_gmt\\\\\\\\\\\\": \\\\\\\\\\\\"2013-07-18 06:29:00\\\\\\\\\\\\", \\\\\\\\\\\\"level\\\\\\\\\\\\": 1}, {\\\\\\\\\\\\"is_remove\\\\\\\\\\\\": false, \\\\\\\\\\\\"index\\\\\\\\\\\\": 5, \\\\\\\\\\\\"has_childs\\\\\\\\\\\\": false, \\\\\\\\\\\\"child_count\\\\\\\\\\\\": 0, \\\\\\\\\\\\"comment_author\\\\\\\\\\\\": \\\\\\\\\\\\"익명-8397\\\\\\\\\\\\", \\\\\\\\\\\\"comment_content\\\\\\\\\\\\": \\\\\\\\\\\\"대구 앞산순환도로 끝자락..작년인가 yf급발진사고난곳 1km쯤전인듯... 저곳에선 자주보는 광경입니다..ㅎㅎ\\\\\\\\\\\\", \\\\\\\\\\\\"comment_karma\\\\\\\\\\\\": 0, \\\\\\\\\\\\"comment_date\\\\\\\\\\\\": \\\\\\\\\\\\"2013-07-18 15:43:00\\\\\\\\\\\\", \\\\\\\\\\\\"comment_date_gmt\\\\\\\\\\\\": \\\\\\\\\\\\"2013-07-18 06:43:00\\\\\\\\\\\\", \\\\\\\\\\\\"level\\\\\\\\\\\\": 1}]}\\\\"}, {\\\\"meta_key\\\\": \\\\"is_source_link\\\\", \\\\"meta_value\\\\": \\\\"1\\\\"}, {\\\\"meta_key\\\\": \\\\"source_link_b64\\\\", \\\\"meta_value\\\\": \\\\"aHR0cHM6Ly93d3cuYm9iYWVkcmVhbS5jby5rci92aWV3P2NvZGU9YmVzdCZObz0yNjIzMCZ2ZGF0ZT1o\\\\"}, {\\\\"meta_key\\\\": \\\\"source_link\\\\", \\\\"meta_value\\\\": \\\\"aHR0cHM6Ly93d3cuYm9iYWVkcmVhbS5jby5rci92aWV3P2NvZGU9YmVzdCZObz0yNjIzMCZ2ZGF0ZT1o\\\\"}, {\\\\"meta_key\\\\": \\\\"source_label\\\\", \\\\"meta_value\\\\": \\\\"보배드림\\\\"}]", "2020-11-23T06:27:00", "2020-11-23T06:27:00", "pending", "2393", "cms_1", "bobae_sender", 1087, "wp_cms_grab") \'] (Background on this error at: http://sqlalche.me/e/2j85)\n', 'msg': '(pymysql.err.InternalError) (1054, "Unknown column \'date_gmt\' in \'field list\'") [SQL: \'INSERT INTO crw_wp_post_map (`sgid`, `date_gmt`, `date_gmt_time`, `update_time`, `seq_num`, `crw_num`, `title`, `content`, `source_link`, `link`, `meta`, `modified_gmt`, `modified_gmt_time`, `status`, `categories`, `cms_iden`, `grab_name`, `ID`, `grabber_type`) VALUES ("47a7aac92d0305319b1fae38c47ca9ce-v7GsUoJW-f87f87ef-84f3-4433-9845-39b64b565495", "2013-07-18T15:06:00", "2013-07-18T15:06:00", "2020-11-23 23:55:40", -1, 1, "국내 감동적인응급차 길터주기 모세의기적", "<p>\\xa0</p><iframe allowfullscreen=\\\\"\\\\" frameborder=\\\\"0\\\\" height=\\\\"360\\\\" src=\\\\"http://www.youtube.com/embed/zX8BwkB4Mfo?feature=player_detailpage\\\\" width=\\\\"640\\\\"></iframe>\\\\n<p>\\xa0</p>\\\\n<p>\\xa0</p>\\\\n<p><span style=\\\\"FONT-SIZE: 12pt\\\\">[펌]</span></p>\\\\n<p><span style=\\\\"FONT-SIZE: 12pt\\\\">이정도면 선진국 아닌가요? 여러분 모두 할 수 있는 </span></p>\\\\n<p><span style=\\\\"FONT-SIZE: 12pt\\\\">그런 평범한 일입니다 조금만 움직이면 한 생명을 살릴수 있습니다 </span></p>\\\\n<p><span style=\\\\"FONT-SIZE: 12pt\\\\">저부터 실천 하겠습니다 (소리주의)</span></p>", "https://www.bobaedream.co.kr/view?code=best&No=26230&vdate=h", "https://commu-crw.moagun.xyz/?p=1087", "[{\\\\"meta_key\\\\": \\\\"is_comment_box\\\\", \\\\"meta_value\\\\": \\\\"1\\\\"}, {\\\\"meta_key\\\\": \\\\"comment_box\\\\", \\\\"meta_value\\\\": \\\\"{\\\\\\\\\\\\"box\\\\\\\\\\\\": \\\\\\\\\\\\"bobae\\\\\\\\\\\\", \\\\\\\\\\\\"comment_list\\\\\\\\\\\\": [{\\\\\\\\\\\\"is_remove\\\\\\\\\\\\": false, \\\\\\\\\\\\"index\\\\\\\\\\\\": 2, \\\\\\\\\\\\"has_childs\\\\\\\\\\\\": false, \\\\\\\\\\\\"child_count\\\\\\\\\\\\": 0, \\\\\\\\\\\\"comment_author\\\\\\\\\\\\": \\\\\\\\\\\\"익명-9194\\\\\\\\\\\\", \\\\\\\\\\\\"comment_content\\\\\\\\\\\\": \\\\\\\\\\\\"오메 소름!\\\\\\\\\\\\", \\\\\\\\\\\\"comment_karma\\\\\\\\\\\\": 0, \\\\\\\\\\\\"comment_date\\\\\\\\\\\\": \\\\\\\\\\\\"2013-07-18 15:22:00\\\\\\\\\\\\", \\\\\\\\\\\\"comment_date_gmt\\\\\\\\\\\\": \\\\\\\\\\\\"2013-07-18 06:22:00\\\\\\\\\\\\", \\\\\\\\\\\\"level\\\\\\\\\\\\": 1}, {\\\\\\\\\\\\"is_remove\\\\\\\\\\\\": false, \\\\\\\\\\\\"index\\\\\\\\\\\\": 3, \\\\\\\\\\\\"has_childs\\\\\\\\\\\\": false, \\\\\\\\\\\\"child_count\\\\\\\\\\\\": 0, \\\\\\\\\\\\"comment_author\\\\\\\\\\\\": \\\\\\\\\\\\"익명-1930\\\\\\\\\\\\", \\\\\\\\\\\\"comment_content\\\\\\\\\\\\": \\\\\\\\\\\\"굿...\\\\\\\\\\\\", \\\\\\\\\\\\"comment_karma\\\\\\\\\\\\": 0, \\\\\\\\\\\\"comment_date\\\\\\\\\\\\": \\\\\\\\\\\\"2013-07-18 15:28:00\\\\\\\\\\\\", \\\\\\\\\\\\"comment_date_gmt\\\\\\\\\\\\": \\\\\\\\\\\\"2013-07-18 06:28:00\\\\\\\\\\\\", \\\\\\\\\\\\"level\\\\\\\\\\\\": 1}, {\\\\\\\\\\\\"is_remove\\\\\\\\\\\\": false, \\\\\\\\\\\\"index\\\\\\\\\\\\": 4, \\\\\\\\\\\\"has_childs\\\\\\\\\\\\": false, \\\\\\\\\\\\"child_count\\\\\\\\\\\\": 0, \\\\\\\\\\\\"comment_author\\\\\\\\\\\\": \\\\\\\\\\\\"익명-1930\\\\\\\\\\\\", \\\\\\\\\\\\"comment_content\\\\\\\\\\\\": \\\\\\\\\\\\"많은분들 볼수있게 추�V...\\\\\\\\\\\\", \\\\\\\\\\\\"comment_karma\\\\\\\\\\\\": 0, \\\\\\\\\\\\"comment_date\\\\\\\\\\\\": \\\\\\\\\\\\"2013-07-18 15:29:00\\\\\\\\\\\\", \\\\\\\\\\\\"comment_date_gmt\\\\\\\\\\\\": \\\\\\\\\\\\"2013-07-18 06:29:00\\\\\\\\\\\\", \\\\\\\\\\\\"level\\\\\\\\\\\\": 1}, {\\\\\\\\\\\\"is_remove\\\\\\\\\\\\": false, \\\\\\\\\\\\"index\\\\\\\\\\\\": 5, \\\\\\\\\\\\"has_childs\\\\\\\\\\\\": false, \\\\\\\\\\\\"child_count\\\\\\\\\\\\": 0, \\\\\\\\\\\\"comment_author\\\\\\\\\\\\": \\\\\\\\\\\\"익명-8397\\\\\\\\\\\\", \\\\\\\\\\\\"comment_content\\\\\\\\\\\\": \\\\\\\\\\\\"대구 앞산순환도로 끝자락..작년인가 yf급발진사고난곳 1km쯤전인듯... 저곳에선 자주보는 광경입니다..ㅎㅎ\\\\\\\\\\\\", \\\\\\\\\\\\"comment_karma\\\\\\\\\\\\": 0, \\\\\\\\\\\\"comment_date\\\\\\\\\\\\": \\\\\\\\\\\\"2013-07-18 15:43:00\\\\\\\\\\\\", \\\\\\\\\\\\"comment_date_gmt\\\\\\\\\\\\": \\\\\\\\\\\\"2013-07-18 06:43:00\\\\\\\\\\\\", \\\\\\\\\\\\"level\\\\\\\\\\\\": 1}]}\\\\"}, {\\\\"meta_key\\\\": \\\\"is_source_link\\\\", \\\\"meta_value\\\\": \\\\"1\\\\"}, {\\\\"meta_key\\\\": \\\\"source_link_b64\\\\", \\\\"meta_value\\\\": \\\\"aHR0cHM6Ly93d3cuYm9iYWVkcmVhbS5jby5rci92aWV3P2NvZGU9YmVzdCZObz0yNjIzMCZ2ZGF0ZT1o\\\\"}, {\\\\"meta_key\\\\": \\\\"source_link\\\\", \\\\"meta_value\\\\": \\\\"aHR0cHM6Ly93d3cuYm9iYWVkcmVhbS5jby5rci92aWV3P2NvZGU9YmVzdCZObz0yNjIzMCZ2ZGF0ZT1o\\\\"}, {\\\\"meta_key\\\\": \\\\"source_label\\\\", \\\\"meta_value\\\\": \\\\"보배드림\\\\"}]", "2020-11-23T06:27:00", "2020-11-23T06:27:00", "pending", "2393", "cms_1", "bobae_sender", 1087, "wp_cms_grab") \'] (Background on this error at: http://sqlalche.me/e/2j85)'} 
 - param_info : {'grab_config': {'client_name': 'sender-commu-silo-bobae.yaml', 'grab_name': 'bobae_sender'}, 'proto': 'postmap_send', 'send_class': 'postmap', 'execute_spider': True, 'request_name': 'bobae-silo'} 

2020-11-24 00:11:58   INFO - flaskSchedulerUnits.py:23  - flask start
2020-11-24 00:12:33  ERROR - tasks_cmsGrabApi.py:55  - postmap_send
2020-11-24 00:19:54   INFO - flaskSchedulerUnits.py:23  - flask start
2020-11-24 00:20:02  ERROR - tasks_cmsGrabApi.py:55  - postmap_send
2020-11-24 05:56:58   INFO - flaskSchedulerUnits.py:23  - flask start
2020-11-24 05:58:13  ERROR - tasks_cmsGrabApi.py:82  - execute : {'errType': 'ConnectionError', 'mode': 'uknown', 'errInfo': {'type': 'ConnectionError', 'traceback': 'Traceback (most recent call last):\n  File "/usr/local/lib/python3.6/dist-packages/urllib3/connection.py", line 159, in _new_conn\n    (self._dns_host, self.port), self.timeout, **extra_kw)\n  File "/usr/local/lib/python3.6/dist-packages/urllib3/util/connection.py", line 80, in create_connection\n    raise err\n  File "/usr/local/lib/python3.6/dist-packages/urllib3/util/connection.py", line 70, in create_connection\n    sock.connect(sa)\nConnectionRefusedError: [Errno 111] Connection refused\n\nDuring handling of the above exception, another exception occurred:\n\nTraceback (most recent call last):\n  File "/usr/local/lib/python3.6/dist-packages/urllib3/connectionpool.py", line 600, in urlopen\n    chunked=chunked)\n  File "/usr/local/lib/python3.6/dist-packages/urllib3/connectionpool.py", line 354, in _make_request\n    conn.request(method, url, **httplib_request_kw)\n  File "/usr/lib/python3.6/http/client.py", line 1239, in request\n    self._send_request(method, url, body, headers, encode_chunked)\n  File "/usr/lib/python3.6/http/client.py", line 1285, in _send_request\n    self.endheaders(body, encode_chunked=encode_chunked)\n  File "/usr/lib/python3.6/http/client.py", line 1234, in endheaders\n    self._send_output(message_body, encode_chunked=encode_chunked)\n  File "/usr/lib/python3.6/http/client.py", line 1026, in _send_output\n    self.send(msg)\n  File "/usr/lib/python3.6/http/client.py", line 964, in send\n    self.connect()\n  File "/usr/local/lib/python3.6/dist-packages/urllib3/connection.py", line 181, in connect\n    conn = self._new_conn()\n  File "/usr/local/lib/python3.6/dist-packages/urllib3/connection.py", line 168, in _new_conn\n    self, "Failed to establish a new connection: %s" % e)\nurllib3.exceptions.NewConnectionError: <urllib3.connection.HTTPConnection object at 0x7f9f29fe0048>: Failed to establish a new connection: [Errno 111] Connection refused\n\nDuring handling of the above exception, another exception occurred:\n\nTraceback (most recent call last):\n  File "/usr/local/lib/python3.6/dist-packages/requests/adapters.py", line 449, in send\n    timeout=timeout\n  File "/usr/local/lib/python3.6/dist-packages/urllib3/connectionpool.py", line 638, in urlopen\n    _stacktrace=sys.exc_info()[2])\n  File "/usr/local/lib/python3.6/dist-packages/urllib3/util/retry.py", line 398, in increment\n    raise MaxRetryError(_pool, url, error or ResponseError(cause))\nurllib3.exceptions.MaxRetryError: HTTPConnectionPool(host=\'211.245.79.107\', port=10081): Max retries exceeded with url: /execute (Caused by NewConnectionError(\'<urllib3.connection.HTTPConnection object at 0x7f9f29fe0048>: Failed to establish a new connection: [Errno 111] Connection refused\',))\n\nDuring handling of the above exception, another exception occurred:\n\nTraceback (most recent call last):\n  File "/headless/app/projects/MiscLib/Utils.py", line 1836, in _request_method\n    res =  session.post(url,**argsDict)\n  File "/usr/local/lib/python3.6/dist-packages/requests/sessions.py", line 572, in post\n    return self.request(\'POST\', url, data=data, json=json, **kwargs)\n  File "/usr/local/lib/python3.6/dist-packages/requests/sessions.py", line 524, in request\n    resp = self.send(prep, **send_kwargs)\n  File "/usr/local/lib/python3.6/dist-packages/requests/sessions.py", line 637, in send\n    r = adapter.send(request, **kwargs)\n  File "/usr/local/lib/python3.6/dist-packages/requests/adapters.py", line 516, in send\n    raise ConnectionError(e, request=request)\nrequests.exceptions.ConnectionError: HTTPConnectionPool(host=\'211.245.79.107\', port=10081): Max retries exceeded with url: /execute (Caused by NewConnectionError(\'<urllib3.connection.HTTPConnection object at 0x7f9f29fe0048>: Failed to establish a new connection: [Errno 111] Connection refused\',))\n', 'msg': "HTTPConnectionPool(host='211.245.79.107', port=10081): Max retries exceeded with url: /execute (Caused by NewConnectionError('<urllib3.connection.HTTPConnection object at 0x7f9f29fe0048>: Failed to establish a new connection: [Errno 111] Connection refused',))"}} 
 - param_info : {'grab_config': {'client_name': 'commu-sender-bobae.yaml', 'grab_name': 'bobae_sender'}, 'proto': 'postmap_send', 'send_class': 'postmap', 'execute_spider': True, 'request_name': 'bobae-silo'} 

2020-11-24 06:11:55   INFO - flaskSchedulerUnits.py:23  - flask start
2020-11-24 06:12:04  ERROR - tasks_cmsGrabApi.py:82  - execute : {'errType': 'HTTPError', 'code': '-1', 'mode': 'http', 'errInfo': {'type': 'HTTPError', 'traceback': 'Traceback (most recent call last):\n  File "/headless/app/projects/MiscLib/Utils.py", line 1874, in _request_method\n    res.raise_for_status()\n  File "/usr/local/lib/python3.6/dist-packages/requests/models.py", line 940, in raise_for_status\n    raise HTTPError(http_error_msg, response=self)\nrequests.exceptions.HTTPError: 404 Client Error: NOT FOUND for url: https://local-test.moagun.xyz/execute\n', 'code': '-1', 'msg': ''}} 
 - param_info : {'grab_config': {'client_name': 'commu-sender-bobae.yaml', 'grab_name': 'bobae_sender'}, 'proto': 'postmap_send', 'send_class': 'postmap', 'execute_spider': True, 'request_name': 'bobae-silo'} 

2020-11-24 06:14:11   INFO - flaskSchedulerUnits.py:23  - flask start
2020-11-24 06:15:22  ERROR - tasks_cmsGrabApi.py:82  - execute : {'errType': 'HTTPError', 'code': '-1', 'mode': 'http', 'errInfo': {'type': 'HTTPError', 'traceback': 'Traceback (most recent call last):\n  File "/headless/app/projects/MiscLib/Utils.py", line 1874, in _request_method\n    res.raise_for_status()\n  File "/usr/local/lib/python3.6/dist-packages/requests/models.py", line 940, in raise_for_status\n    raise HTTPError(http_error_msg, response=self)\nrequests.exceptions.HTTPError: 502 Server Error: Bad Gateway for url: https://local-test.moagun.xyz/ctask/check\n', 'code': '-1', 'msg': ''}} 
 - param_info : {'grab_config': {'client_name': 'commu-sender-bobae.yaml', 'grab_name': 'bobae_sender'}, 'proto': 'postmap_send', 'send_class': 'postmap', 'execute_spider': True, 'request_name': 'bobae-silo'} 

